Workbook
Name _00시: #REF!
Name _shcnf: #REF!
Name _tt2: #REF!
Name \0: #REF!
Name \ADL_KID: #REF!
Name \c: #N/A
Name \d: #REF!
Name \i: #REF!
Name \KOBACO: #REF!
Name \m: #REF!
Name \p: #N/A
Name \q: #N/A
Name a: #REF!
Name All: #REF!
Name asd: #REF!
Name asdf: #REF!
Name ASDFASDFGASD: #REF!
Name bcrclcl100rt: '[1]9-1차이내역'!#REF!
Name bcrclcl100rtrkrk: '[1]9-1차이내역'!#REF!
Name BFX_BRANDFX: 60122
Name Channel: #REF!
Name CHINA: #REF!
Name conb1: [1]!conb1
Name conb10: [1]!conb10
Name conb100: [1]!conb100
Name conb101: [1]!conb101
Name conb102: [1]!conb102
Name conb103: [1]!conb103
Name conb104: [1]!conb104
Name conb105: [1]!conb105
Name conb106: [1]!conb106
Name conb107: [1]!conb107
Name conb108: [1]!conb108
Name conb109: [1]!conb109
Name conb11: [1]!conb11
Name conb110: [1]!conb110
Name conb111: [1]!conb111
Name conb112: [1]!conb112
Name conb113: [1]!conb113
Name conb114: [1]!conb114
Name conb115: [1]!conb115
Name conb116: [1]!conb116
Name conb117: [1]!conb117
Name conb118: [1]!conb118
Name conb119: [1]!conb119
Name conb12: [1]!conb12
Name conb120: [1]!conb120
Name conb121: [1]!conb121
Name conb13: [1]!conb13
Name conb14: [1]!conb14
Name conb15: [1]!conb15
Name conb16: [1]!conb16
Name conb17: [1]!conb17
Name conb18: [1]!conb18
Name conb19: [1]!conb19
Name conb2: [1]!conb2
Name conb20: [1]!conb20
Name conb200: [1]!conb88
Name conb21: [1]!conb21
Name conb22: [1]!conb22

Sheet DAILY
A1: 상담일자 | B1: Dnis | C1: Channel | D1: 소재 | E1: 광고비 | F1: 광고횟수 | G1: I/B콜수 | H1: 응대호 | I1: 정기건수 | J1: 정기금액 | K1: 일시건수 | L1: 일시금액 | M1: 응대율 | N1: 콜전환율 | O1: 정기전환율 | P1: CPR | Q1: ROI
A2: 46023 | B2: 1899-0218 | C2: EBS | D2: 식사지원 은영이ver2 | E2: 1420261.1 | F2: 3 | G2: 17 | H2: 12 | I2: 6 | J2: 130000 | K2: 1 | L2: 20000 | M2: =IFERROR(H2/G2,0) -> 0.70588235 | N2: =IFERROR(G2/F2,0) -> 5.6666667 | O2: =IFERROR(I2/H2,0) -> 0.5 | P2: =IFERROR(E2/G2,0) -> 83544.769 | Q2: =IFERROR(J2*12/E2,0) -> 1.0983896
A3: 46023 | B3: 1899-0219 | C3: SPOTV | D3: 식사지원 지영이 | E3: 248120.3 | F3: 6 | G3: 4 | H3: 3 | M3: =IFERROR(H3/G3,0) -> 0.75 | N3: =IFERROR(G3/F3,0) -> 0.66666667 | O3: =IFERROR(I3/H3,0) -> 0 | P3: =IFERROR(E3/G3,0) -> 62030.075 | Q3: =IFERROR(J3*12/E3,0) -> 0
A4: 46023 | B4: 1899-0519 | C4: SPOTV2 | D4: 난방비 동하 | E4: 177419.35 | F4: 4 | G4: 1 | H4: 1 | M4: =IFERROR(H4/G4,0) -> 1 | N4: =IFERROR(G4/F4,0) -> 0.25 | O4: =IFERROR(I4/H4,0) -> 0 | P4: =IFERROR(E4/G4,0) -> 177419.35 | Q4: =IFERROR(J4*12/E4,0) -> 0
A5: 46023 | B5: 1899-0325 | C5: SPOTV G&H (SVC) | D5: 식사지원 지영이 | E5: 0 | F5: 5 | G5: 1 | I5: 1 | J5: 20000 | M5: =IFERROR(H5/G5,0) -> 0 | N5: =IFERROR(G5/F5,0) -> 0.2 | O5: =IFERROR(I5/H5,0) -> 0 | P5: =IFERROR(E5/G5,0) -> 0 | Q5: =IFERROR(J5*12/E5,0) -> 0
A6: 46023 | B6: 1899-7319 | C6: JTBC4 | D6: 은영이 셀럽 | E6: 184256 | F6: 5 | G6: 2 | H6: 1 | I6: - | J6: - | K6: - | L6: - | M6: =IFERROR(H6/G6,0) -> 0.5 | N6: =IFERROR(G6/F6,0) -> 0.4 | O6: =IFERROR(I6/H6,0) -> 0 | P6: =IFERROR(E6/G6,0) -> 92128 | Q6: =IFERROR(J6*12/E6,0) -> 0
A7: 46023 | B7: 1899-0762 | C7: JTBC4 | D7: 식사지원 은영이 ver2 | E7: 331660 | F7: 9 | G7: 2 | H7: 2 | I7: - | J7: - | K7: 1 | L7: 20000 | M7: =IFERROR(H7/G7,0) -> 1 | N7: =IFERROR(G7/F7,0) -> 0.22222222 | O7: =IFERROR(I7/H7,0) -> 0 | P7: =IFERROR(E7/G7,0) -> 165830 | Q7: =IFERROR(J7*12/E7,0) -> 0
A8: 46023 | B8: 1899-7318 | C8: JTBC4 | D8: 가족돌봄 지수 | E8: 331660 | F8: 9 | G8: - | H8: - | I8: - | J8: - | K8: - | L8: - | M8: =IFERROR(H8/G8,0) -> 0 | N8: =IFERROR(G8/F8,0) -> 0 | O8: =IFERROR(I8/H8,0) -> 0 | P8: =IFERROR(E8/G8,0) -> 0 | Q8: =IFERROR(J8*12/E8,0) -> 0
A9: 46023 | B9: 1899-7316 | C9: JTBC4 | D9: 식사지원 준우_셰프 | E9: 184256 | F9: 5 | G9: 1 | H9: 1 | I9: - | J9: - | K9: - | L9: - | M9: =IFERROR(H9/G9,0) -> 1 | N9: =IFERROR(G9/F9,0) -> 0.2 | O9: =IFERROR(I9/H9,0) -> 0 | P9: =IFERROR(E9/G9,0) -> 184256 | Q9: =IFERROR(J9*12/E9,0) -> 0
A10: 46023 | B10: 1899-2887 | C10: JTBC4 | D10: 식사지원 준우_메인 | E10: 184256 | F10: 5 | G10: 2 | H10: 2 | I10: 1 | J10: 25000 | K10: - | L10: - | M10: =IFERROR(H10/G10,0) -> 1 | N10: =IFERROR(G10/F10,0) -> 0.4 | O10: =IFERROR(I10/H10,0) -> 0.5 | P10: =IFERROR(E10/G10,0) -> 92128 | Q10: =IFERROR(J10*12/E10,0) -> 1.6281695
A11: 46023 | B11: 1899-0795 | C11: JTBC4 | D11: 식사지원 준우_아동 | E11: 184256 | F11: 5 | G11: - | H11: - | I11: - | J11: - | K11: - | L11: - | M11: =IFERROR(H11/G11,0) -> 0 | N11: =IFERROR(G11/F11,0) -> 0 | O11: =IFERROR(I11/H11,0) -> 0 | P11: =IFERROR(E11/G11,0) -> 0 | Q11: =IFERROR(J11*12/E11,0) -> 0
A12: 46023 | B12: 1899-3569 | C12: JTBC4 | D12: 식사지원 준우_할머니 | E12: 184256 | F12: 5 | G12: - | H12: - | I12: - | J12: - | K12: - | L12: - | M12: =IFERROR(H12/G12,0) -> 0 | N12: =IFERROR(G12/F12,0) -> 0 | O12: =IFERROR(I12/H12,0) -> 0 | P12: =IFERROR(E12/G12,0) -> 0 | Q12: =IFERROR(J12*12/E12,0) -> 0
A13: 46023 | B13: 1899-7325 | C13: JTBC4 | D13: 난방비 동하 | E13: 147405 | F13: 4 | G13: 4 | H13: 3 | I13: 3 | J13: 55000 | K13: - | L13: - | M13: =IFERROR(H13/G13,0) -> 0.75 | N13: =IFERROR(G13/F13,0) -> 1 | O13: =IFERROR(I13/H13,0) -> 1 | P13: =IFERROR(E13/G13,0) -> 36851.25 | Q13: =IFERROR(J13*12/E13,0) -> 4.4774601
A14: 46023 | B14: 1899-7326 | C14: JTBC2 (SVC) | D14: 난방비 동하 | E14: 0 | F14: 1 | G14: 1 | H14: 1 | K14: 1 | L14: 20000 | M14: =IFERROR(H14/G14,0) -> 1 | N14: =IFERROR(G14/F14,0) -> 1 | O14: =IFERROR(I14/H14,0) -> 0 | P14: =IFERROR(E14/G14,0) -> 0 | Q14: =IFERROR(J14*12/E14,0) -> 0
A15: 46023 | B15: 1899-0217 | C15: 빌리어즈TV | D15: 식사지원 은영이_콜문구 | E15: 285714.29 | F15: 4 | M15: =IFERROR(H15/G15,0) -> 0 | N15: =IFERROR(G15/F15,0) -> 0 | O15: =IFERROR(I15/H15,0) -> 0 | P15: =IFERROR(E15/G15,0) -> 0 | Q15: =IFERROR(J15*12/E15,0) -> 0
A16: 46023 | B16: 1899-0263 | C16: 바둑TV | D16: 식사지원 지영이 | E16: 122222.22 | F16: 4 | M16: =IFERROR(H16/G16,0) -> 0 | N16: =IFERROR(G16/F16,0) -> 0 | O16: =IFERROR(I16/H16,0) -> 0 | P16: =IFERROR(E16/G16,0) -> 0 | Q16: =IFERROR(J16*12/E16,0) -> 0
A17: 46023 | B17: 1899-0739 | C17: CNTV | D17: 난방비 동하 | E17: 206250 | F17: 3 | M17: =IFERROR(H17/G17,0) -> 0 | N17: =IFERROR(G17/F17,0) -> 0 | O17: =IFERROR(I17/H17,0) -> 0 | P17: =IFERROR(E17/G17,0) -> 0 | Q17: =IFERROR(J17*12/E17,0) -> 0
A18: 46023 | B18: 1899-0776 | C18: 라이프타임 | D18: 가족돌봄 지수ver2 | E18: 187234.04 | F18: 4 | G18: 3 | H18: 3 | I18: 2 | J18: 40000 | M18: =IFERROR(H18/G18,0) -> 1 | N18: =IFERROR(G18/F18,0) -> 0.75 | O18: =IFERROR(I18/H18,0) -> 0.66666667 | P18: =IFERROR(E18/G18,0) -> 62411.348 | Q18: =IFERROR(J18*12/E18,0) -> 2.5636364
A19: 46023 | B19: 1899-7314 | C19: 히스토리 (SVC) | D19: 식사지원 지영이 | E19: 0 | F19: 7 | M19: =IFERROR(H19/G19,0) -> 0 | N19: =IFERROR(G19/F19,0) -> 0 | O19: =IFERROR(I19/H19,0) -> 0 | P19: =IFERROR(E19/G19,0) -> 0 | Q19: =IFERROR(J19*12/E19,0) -> 0
A20: 46023 | B20: 1899-5186 | C20: 시네마천국 | D20: 식사지원 지영이 | E20: 283870.97 | F20: 9 | G20: 1 | H20: 1 | I20: 1 | J20: 20000 | M20: =IFERROR(H20/G20,0) -> 1 | N20: =IFERROR(G20/F20,0) -> 0.11111111 | O20: =IFERROR(I20/H20,0) -> 1 | P20: =IFERROR(E20/G20,0) -> 283870.97 | Q20: =IFERROR(J20*12/E20,0) -> 0.84545455
A21: 46023 | B21: 1899-3854 | C21: 채널J | D21: 식사지원 은영이ver2 | E21: 225409.84 | F21: 4 | G21: 1 | H21: 1 | I21: 1 | J21: 20000 | M21: =IFERROR(H21/G21,0) -> 1 | N21: =IFERROR(G21/F21,0) -> 0.25 | O21: =IFERROR(I21/H21,0) -> 1 | P21: =IFERROR(E21/G21,0) -> 225409.84 | Q21: =IFERROR(J21*12/E21,0) -> 1.0647273
A22: 46023 | B22: 1899-7317 | C22: 애니원, 애니박스 (SVC) | D22: 식사지원 은영이ver2 | E22: 0 | F22: 8 | M22: =IFERROR(H22/G22,0) -> 0 | N22: =IFERROR(G22/F22,0) -> 0 | O22: =IFERROR(I22/H22,0) -> 0 | P22: =IFERROR(E22/G22,0) -> 0 | Q22: =IFERROR(J22*12/E22,0) -> 0
A23: 46023 | B23: 1899-7315 | C23: 중화TV | D23: 식사지원 은영이_콜문구 | E23: 528846.15 | F23: 4 | G23: 1 | H23: 1 | K23: 1 | L23: 120000 | M23: =IFERROR(H23/G23,0) -> 1 | N23: =IFERROR(G23/F23,0) -> 0.25 | O23: =IFERROR(I23/H23,0) -> 0 | P23: =IFERROR(E23/G23,0) -> 528846.15 | Q23: =IFERROR(J23*12/E23,0) -> 0
A24: 46023 | B24: - | C24: 기타 TV채널 | D24: - | E24: 0 | F24: 0 | I24: 1 | J24: 30000 | M24: =IFERROR(H24/G24,0) -> 0 | N24: =IFERROR(G24/F24,0) -> 0 | O24: =IFERROR(I24/H24,0) -> 0 | P24: =IFERROR(E24/G24,0) -> 0 | Q24: =IFERROR(J24*12/E24,0) -> 0
A25: 46023 | B25: 2102-4590 | C25: 발신 | D25: - | E25: 0 | F25: 0 | G25: 2 | H25: 1 | M25: =IFERROR(H25/G25,0) -> 0.5 | N25: =IFERROR(G25/F25,0) -> 0 | O25: =IFERROR(I25/H25,0) -> 0 | P25: =IFERROR(E25/G25,0) -> 0 | Q25: =IFERROR(J25*12/E25,0) -> 0
A26: 46024 | B26: 1899-0218 | C26: EBS | D26: 식사지원 은영이ver2 | E26: 2032065.8 | F26: 4 | G26: 12 | H26: 7 | I26: 2 | J26: 30000 | K26: 2 | L26: 70000 | M26: =IFERROR(H26/G26,0) -> 0.58333333 | N26: =IFERROR(G26/F26,0) -> 3 | O26: =IFERROR(I26/H26,0) -> 0.28571429 | P26: =IFERROR(E26/G26,0) -> 169338.82 | Q26: =IFERROR(J26*12/E26,0) -> 0.17715961
A27: 46024 | B27: 1899-0219 | C27: SPOTV | D27: 식사지원 지영이 | E27: 165413.53 | F27: 4 | M27: =IFERROR(H27/G27,0) -> 0 | N27: =IFERROR(G27/F27,0) -> 0 | O27: =IFERROR(I27/H27,0) -> 0 | P27: =IFERROR(E27/G27,0) -> 0 | Q27: =IFERROR(J27*12/E27,0) -> 0
A28: 46024 | B28: 1899-0519 | C28: SPOTV2 | D28: 난방비 동하 | E28: 177419.35 | F28: 4 | M28: =IFERROR(H28/G28,0) -> 0 | N28: =IFERROR(G28/F28,0) -> 0 | O28: =IFERROR(I28/H28,0) -> 0 | P28: =IFERROR(E28/G28,0) -> 0 | Q28: =IFERROR(J28*12/E28,0) -> 0
A29: 46024 | B29: 1899-0325 | C29: SPOTV G&H (SVC) | D29: 식사지원 지영이 | E29: 0 | F29: 5 | M29: =IFERROR(H29/G29,0) -> 0 | N29: =IFERROR(G29/F29,0) -> 0 | O29: =IFERROR(I29/H29,0) -> 0 | P29: =IFERROR(E29/G29,0) -> 0 | Q29: =IFERROR(J29*12/E29,0) -> 0
A30: 46024 | B30: 1899-7319 | C30: JTBC4 | D30: 은영이 셀럽 | E30: 154541 | F30: 4 | G30: 2 | H30: 2 | I30: 1 | J30: 20000 | K30: - | L30: - | M30: =IFERROR(H30/G30,0) -> 1 | N30: =IFERROR(G30/F30,0) -> 0.5 | O30: =IFERROR(I30/H30,0) -> 0.5 | P30: =IFERROR(E30/G30,0) -> 77270.5 | Q30: =IFERROR(J30*12/E30,0) -> 1.5529859
A31: 46024 | B31: 1899-0762 | C31: JTBC4 | D31: 식사지원 은영이 ver2 | E31: 347715 | F31: 9 | G31: 2 | H31: 1 | I31: - | J31: - | K31: - | L31: - | M31: =IFERROR(H31/G31,0) -> 0.5 | N31: =IFERROR(G31/F31,0) -> 0.22222222 | O31: =IFERROR(I31/H31,0) -> 0 | P31: =IFERROR(E31/G31,0) -> 173857.5 | Q31: =IFERROR(J31*12/E31,0) -> 0
A32: 46024 | B32: 1899-7318 | C32: JTBC4 | D32: 가족돌봄 지수 | E32: 347715 | F32: 9 | G32: 8 | H32: 7 | I32: 3 | J32: 65000 | K32: - | L32: - | M32: =IFERROR(H32/G32,0) -> 0.875 | N32: =IFERROR(G32/F32,0) -> 0.88888889 | O32: =IFERROR(I32/H32,0) -> 0.42857143 | P32: =IFERROR(E32/G32,0) -> 43464.375 | Q32: =IFERROR(J32*12/E32,0) -> 2.2432164
A33: 46024 | B33: 1899-7316 | C33: JTBC4 | D33: 식사지원 준우_셰프 | E33: 154541 | F33: 4 | G33: 2 | H33: 2 | I33: 2 | J33: 50000 | K33: - | L33: - | M33: =IFERROR(H33/G33,0) -> 1 | N33: =IFERROR(G33/F33,0) -> 0.5 | O33: =IFERROR(I33/H33,0) -> 1 | P33: =IFERROR(E33/G33,0) -> 77270.5 | Q33: =IFERROR(J33*12/E33,0) -> 3.8824648
A34: 46024 | B34: 1899-2887 | C34: JTBC4 | D34: 식사지원 준우_메인 | E34: 154541 | F34: 4 | G34: - | H34: - | I34: - | J34: - | K34: - | L34: - | M34: =IFERROR(H34/G34,0) -> 0 | N34: =IFERROR(G34/F34,0) -> 0 | O34: =IFERROR(I34/H34,0) -> 0 | P34: =IFERROR(E34/G34,0) -> 0 | Q34: =IFERROR(J34*12/E34,0) -> 0
A35: 46024 | B35: 1899-0795 | C35: JTBC4 | D35: 식사지원 준우_아동 | E35: 154541 | F35: 4 | G35: 3 | H35: 2 | I35: - | J35: - | K35: 1 | L35: 100000 | M35: =IFERROR(H35/G35,0) -> 0.66666667 | N35: =IFERROR(G35/F35,0) -> 0.75 | O35: =IFERROR(I35/H35,0) -> 0 | P35: =IFERROR(E35/G35,0) -> 51513.667 | Q35: =IFERROR(J35*12/E35,0) -> 0
A36: 46024 | B36: 1899-3569 | C36: JTBC4 | D36: 식사지원 준우_할머니 | E36: 154541 | F36: 4 | G36: 1 | H36: - | I36: 1 | J36: 25000 | K36: - | L36: - | M36: =IFERROR(H36/G36,0) -> 0 | N36: =IFERROR(G36/F36,0) -> 0.25 | O36: =IFERROR(I36/H36,0) -> 0 | P36: =IFERROR(E36/G36,0) -> 154541 | Q36: =IFERROR(J36*12/E36,0) -> 1.9412324
A37: 46024 | B37: 1899-7325 | C37: JTBC4 | D37: 난방비 동하 | E37: 193176 | F37: 5 | G37: 1 | H37: 1 | I37: 1 | J37: 20000 | K37: - | L37: - | M37: =IFERROR(H37/G37,0) -> 1 | N37: =IFERROR(G37/F37,0) -> 0.2 | O37: =IFERROR(I37/H37,0) -> 1 | P37: =IFERROR(E37/G37,0) -> 193176 | Q37: =IFERROR(J37*12/E37,0) -> 1.2423904
A38: 46024 | B38: 1899-7326 | C38: JTBC2 (SVC) | D38: 난방비 동하 | E38: 0 | F38: 1 | G38: 1 | H38: 1 | I38: 1 | J38: 25000 | M38: =IFERROR(H38/G38,0) -> 1 | N38: =IFERROR(G38/F38,0) -> 1 | O38: =IFERROR(I38/H38,0) -> 1 | P38: =IFERROR(E38/G38,0) -> 0 | Q38: =IFERROR(J38*12/E38,0) -> 0
A39: 46024 | B39: 1899-0217 | C39: 빌리어즈TV | D39: 식사지원 은영이_콜문구 | E39: 285714.29 | F39: 4 | G39: 2 | H39: 2 | I39: 1 | J39: 20000 | M39: =IFERROR(H39/G39,0) -> 1 | N39: =IFERROR(G39/F39,0) -> 0.5 | O39: =IFERROR(I39/H39,0) -> 0.5 | P39: =IFERROR(E39/G39,0) -> 142857.14 | Q39: =IFERROR(J39*12/E39,0) -> 0.84
A40: 46024 | B40: 1899-0263 | C40: 바둑TV | D40: 식사지원 지영이 | E40: 229166.67 | F40: 6 | G40: 2 | H40: 1 | I40: 1 | J40: 30000 | M40: =IFERROR(H40/G40,0) -> 0.5 | N40: =IFERROR(G40/F40,0) -> 0.33333333 | O40: =IFERROR(I40/H40,0) -> 1 | P40: =IFERROR(E40/G40,0) -> 114583.33 | Q40: =IFERROR(J40*12/E40,0) -> 1.5709091
...

Sheet Sheet1
B4: 46023 | C4: =SUMIFS(DAILY!$G$2:$G$685,DAILY!$C$2:$C$685,"JTBC4",DAILY!$A$2:$A$685,B4) -> 11 | J4: 11 | M4: =C4-J4 -> 0
B5: 46024 | C5: =SUMIFS(DAILY!$G$2:$G$685,DAILY!$C$2:$C$685,"JTBC4",DAILY!$A$2:$A$685,B5) -> 19 | J5: 19 | M5: =C5-J5 -> 0
B6: 46025 | C6: =SUMIFS(DAILY!$G$2:$G$685,DAILY!$C$2:$C$685,"JTBC4",DAILY!$A$2:$A$685,B6) -> 13 | J6: 13 | M6: =C6-J6 -> 0
B7: 46026 | C7: =SUMIFS(DAILY!$G$2:$G$685,DAILY!$C$2:$C$685,"JTBC4",DAILY!$A$2:$A$685,B7) -> 7 | J7: 7 | M7: =C7-J7 -> 0
B8: 46027 | C8: =SUMIFS(DAILY!$G$2:$G$685,DAILY!$C$2:$C$685,"JTBC4",DAILY!$A$2:$A$685,B8) -> 17 | J8: 17 | M8: =C8-J8 -> 0
B9: 46028 | C9: =SUMIFS(DAILY!$G$2:$G$685,DAILY!$C$2:$C$685,"JTBC4",DAILY!$A$2:$A$685,B9) -> 15 | J9: 15 | M9: =C9-J9 -> 0
B10: 46029 | C10: =SUMIFS(DAILY!$G$2:$G$685,DAILY!$C$2:$C$685,"JTBC4",DAILY!$A$2:$A$685,B10) -> 12 | J10: 12 | M10: =C10-J10 -> 0
B11: 46030 | C11: =SUMIFS(DAILY!$G$2:$G$685,DAILY!$C$2:$C$685,"JTBC4",DAILY!$A$2:$A$685,B11) -> 9 | J11: 9 | M11: =C11-J11 -> 0
B12: 46031 | C12: =SUMIFS(DAILY!$G$2:$G$685,DAILY!$C$2:$C$685,"JTBC4",DAILY!$A$2:$A$685,B12) -> 9 | J12: 9 | M12: =C12-J12 -> 0
B13: 46032 | C13: =SUMIFS(DAILY!$G$2:$G$685,DAILY!$C$2:$C$685,"JTBC4",DAILY!$A$2:$A$685,B13) -> 15 | J13: 15 | M13: =C13-J13 -> 0
B14: 46033 | C14: =SUMIFS(DAILY!$G$2:$G$685,DAILY!$C$2:$C$685,"JTBC4",DAILY!$A$2:$A$685,B14) -> 16 | J14: 16 | M14: =C14-J14 -> 0
B15: 46034 | C15: =SUMIFS(DAILY!$G$2:$G$685,DAILY!$C$2:$C$685,"JTBC4",DAILY!$A$2:$A$685,B15) -> 9 | J15: 9 | M15: =C15-J15 -> 0
... B34: 46053 | C34: =SUMIFS(DAILY!$G$2:$G$685,DAILY!$C$2:$C$685,"JTBC4",DAILY!$A$2:$A$685,B34) -> 12 | J34: 12 | M34: =C34-J34 -> 0
